Workbook

Sheet Datos
A1: id | B1: Nombre | C1: Comuna | D1: Sector
A2: 1 | B2: Estrella Sevilla | C2: Las Condes | D2: =INDEX('Comuna por Sector'!$B$2:$D$53,MATCH(Datos!C2,'Comuna por Sector'!$B$2:$B$53,0),2) -> Nororiente (Sector Oriente)
A3: 2 | B3: Brigida Guijarro | C3: El Bosque | D3: =INDEX('Comuna por Sector'!$B$2:$D$53,MATCH(Datos!C3,'Comuna por Sector'!$B$2:$B$53,0),2) -> Sur
A4: 3 | B4: Julia Andres | D4: =INDEX('Comuna por Sector'!$B$2:$D$53,MATCH(Datos!C4,'Comuna por Sector'!$B$2:$B$53,0),2) -> #N/A
A5: 4 | B5: Marwa Zheng | C5: Estación Central | D5: =INDEX('Comuna por Sector'!$B$2:$D$53,MATCH(Datos!C5,'Comuna por Sector'!$B$2:$B$53,0),2) -> Centro
A6: 5 | B6: Valentin Burgos | C6: Providencia | D6: =INDEX('Comuna por Sector'!$B$2:$D$53,MATCH(Datos!C6,'Comuna por Sector'!$B$2:$B$53,0),2) -> Nororiente (Sector Oriente)
A7: 6 | B7: Rachid Palomares | C7: Lo Espejo | D7: =INDEX('Comuna por Sector'!$B$2:$D$53,MATCH(Datos!C7,'Comuna por Sector'!$B$2:$B$53,0),2) -> Sur
A8: 7 | B8: Eduard Molinero | C8: Vitacura | D8: =INDEX('Comuna por Sector'!$B$2:$D$53,MATCH(Datos!C8,'Comuna por Sector'!$B$2:$B$53,0),2) -> Nororiente (Sector Oriente)
A9: 8 | B9: Azucena Cantero | C9: Macul | D9: =INDEX('Comuna por Sector'!$B$2:$D$53,MATCH(Datos!C9,'Comuna por Sector'!$B$2:$B$53,0),2) -> Suroriente
A10: 9 | B10: Mateo Beltran | C10: Maipú | D10: =INDEX('Comuna por Sector'!$B$2:$D$53,MATCH(Datos!C10,'Comuna por Sector'!$B$2:$B$53,0),2) -> Surponiente
A11: 10 | B11: Patricio Leiva | D11: =INDEX('Comuna por Sector'!$B$2:$D$53,MATCH(Datos!C11,'Comuna por Sector'!$B$2:$B$53,0),2) -> #N/A
A12: 11 | B12: Iluminada Villar | C12: Huechuraba | D12: =INDEX('Comuna por Sector'!$B$2:$D$53,MATCH(Datos!C12,'Comuna por Sector'!$B$2:$B$53,0),2) -> Norte
A13: 12 | B13: Alfonso Muñiz | C13: La Florida | D13: =INDEX('Comuna por Sector'!$B$2:$D$53,MATCH(Datos!C13,'Comuna por Sector'!$B$2:$B$53,0),2) -> Suroriente
A14: 13 | B14: Matilde de Leon | C14: Las Condes | D14: =INDEX('Comuna por Sector'!$B$2:$D$53,MATCH(Datos!C14,'Comuna por Sector'!$B$2:$B$53,0),2) -> Nororiente (Sector Oriente)
A15: 14 | B15: Francisca Ballester | C15: Peñalolén | D15: =INDEX('Comuna por Sector'!$B$2:$D$53,MATCH(Datos!C15,'Comuna por Sector'!$B$2:$B$53,0),2) -> Suroriente
A16: 15 | B16: Erika de Castro | C16: Colina | D16: =INDEX('Comuna por Sector'!$B$2:$D$53,MATCH(Datos!C16,'Comuna por Sector'!$B$2:$B$53,0),2) -> Norte
A17: 16 | B17: Florin Conesa | C17: San Joaquín | D17: =INDEX('Comuna por Sector'!$B$2:$D$53,MATCH(Datos!C17,'Comuna por Sector'!$B$2:$B$53,0),2) -> Centro
A18: 17 | C18: Renca | D18: =INDEX('Comuna por Sector'!$B$2:$D$53,MATCH(Datos!C18,'Comuna por Sector'!$B$2:$B$53,0),2) -> Norponiente (Sector Poniente)
A19: 18 | B19: Emilia Sepulveda | C19: Conchalí | D19: =INDEX('Comuna por Sector'!$B$2:$D$53,MATCH(Datos!C19,'Comuna por Sector'!$B$2:$B$53,0),2) -> Norte
A20: 19 | B20: Inocencia Manrique | C20: San Miguel | D20: =INDEX('Comuna por Sector'!$B$2:$D$53,MATCH(Datos!C20,'Comuna por Sector'!$B$2:$B$53,0),2) -> Centro
A21: 20 | B21: Visitacion Urbano | C21: Cerrillos | D21: =INDEX('Comuna por Sector'!$B$2:$D$53,MATCH(Datos!C21,'Comuna por Sector'!$B$2:$B$53,0),2) -> Surponiente
A22: 21 | B22: Braulio de Diego | C22: Lo Prado | D22: =INDEX('Comuna por Sector'!$B$2:$D$53,MATCH(Datos!C22,'Comuna por Sector'!$B$2:$B$53,0),2) -> Norponiente (Sector Poniente)
A23: 22 | B23: Arantxa Cubero | C23: Maipú | D23: =INDEX('Comuna por Sector'!$B$2:$D$53,MATCH(Datos!C23,'Comuna por Sector'!$B$2:$B$53,0),2) -> Surponiente
A24: 23 | B24: Aroa Ferreira | C24: Recoleta | D24: =INDEX('Comuna por Sector'!$B$2:$D$53,MATCH(Datos!C24,'Comuna por Sector'!$B$2:$B$53,0),2) -> Norte
A25: 24 | B25: Catalina Elvira | C25: Pudahuel | D25: =INDEX('Comuna por Sector'!$B$2:$D$53,MATCH(Datos!C25,'Comuna por Sector'!$B$2:$B$53,0),2) -> Norponiente (Sector Poniente)
A26: 25 | B26: Joaquim Chaves | C26: Independencia | D26: =INDEX('Comuna por Sector'!$B$2:$D$53,MATCH(Datos!C26,'Comuna por Sector'!$B$2:$B$53,0),2) -> Norte
A27: 26 | B27: Toni Bello | C27: La Cisterna | D27: =INDEX('Comuna por Sector'!$B$2:$D$53,MATCH(Datos!C27,'Comuna por Sector'!$B$2:$B$53,0),2) -> Sur
A28: 27 | B28: Elia Yañez | C28: Huechuraba | D28: =INDEX('Comuna por Sector'!$B$2:$D$53,MATCH(Datos!C28,'Comuna por Sector'!$B$2:$B$53,0),2) -> Norte
A29: 28 | B29: Julio Almagro | C29: Vitacura | D29: =INDEX('Comuna por Sector'!$B$2:$D$53,MATCH(Datos!C29,'Comuna por Sector'!$B$2:$B$53,0),2) -> Nororiente (Sector Oriente)
A30: 29 | B30: Dani Sobrino | C30: Estación Central | D30: =INDEX('Comuna por Sector'!$B$2:$D$53,MATCH(Datos!C30,'Comuna por Sector'!$B$2:$B$53,0),2) -> Centro
... A34: 33 | B34: Felicitas Tapia | C34: La Reina | D34: =INDEX('Comuna por Sector'!$B$2:$D$53,MATCH(Datos!C34,'Comuna por Sector'!$B$2:$B$53,0),2) -> Nororiente (Sector Oriente)
A35: 34 | B35: Alex Flores | D35: =INDEX('Comuna por Sector'!$B$2:$D$53,MATCH(Datos!C35,'Comuna por Sector'!$B$2:$B$53,0),2) -> #N/A
A36: 35 | B36: Ane Buendia | C36: Ñuñoa | D36: =INDEX('Comuna por Sector'!$B$2:$D$53,MATCH(Datos!C36,'Comuna por Sector'!$B$2:$B$53,0),2) -> Nororiente (Sector Oriente)
A37: 36 | B37: Desiree Ferrero | C37: Lo Barnechea | D37: =INDEX('Comuna por Sector'!$B$2:$D$53,MATCH(Datos!C37,'Comuna por Sector'!$B$2:$B$53,0),2) -> Nororiente (Sector Oriente)
A38: 37 | B38: Justo Bermudez | C38: La Cisterna | D38: =INDEX('Comuna por Sector'!$B$2:$D$53,MATCH(Datos!C38,'Comuna por Sector'!$B$2:$B$53,0),2) -> Sur
A39: 38 | B39: Benito Rodrguez | C39: Conchalí | D39: =INDEX('Comuna por Sector'!$B$2:$D$53,MATCH(Datos!C39,'Comuna por Sector'!$B$2:$B$53,0),2) -> Norte
A40: 39 | B40: Teo Salas | C40: San Joaquín | D40: =INDEX('Comuna por Sector'!$B$2:$D$53,MATCH(Datos!C40,'Comuna por Sector'!$B$2:$B$53,0),2) -> Centro
A41: 40 | B41: Emilio Chaparro | C41: Independencia | D41: =INDEX('Comuna por Sector'!$B$2:$D$53,MATCH(Datos!C41,'Comuna por Sector'!$B$2:$B$53,0),2) -> Norte
A42: 41 | B42: Ana Gimeno | C42: La Granja | D42: =INDEX('Comuna por Sector'!$B$2:$D$53,MATCH(Datos!C42,'Comuna por Sector'!$B$2:$B$53,0),2) -> Sur
A43: 42 | B43: Samira Guirado | C43: Colina | D43: =INDEX('Comuna por Sector'!$B$2:$D$53,MATCH(Datos!C43,'Comuna por Sector'!$B$2:$B$53,0),2) -> Norte
...

Sheet Tabla Dinámica
A3: Etiquetas de fila | B3: Cuenta de Comuna
A4: Cerrillos | B4: 2
A5: Cerro Navia | B5: 1
A6: Conchalí | B6: 2
A7: El Bosque | B7: 1
A8: Estación Central | B8: 2
A9: Huechuraba | B9: 2
A10: Independencia | B10: 2
A11: La Cisterna | B11: 2
A12: La Florida | B12: 1
A13: La Granja | B13: 2
A14: La Reina | B14: 1
A15: Las Condes | B15: 2
... A29: Vitacura | B29: 2
A30: (en blanco)
A31: Colina | B31: 2
A32: Padre Hurtado | B32: 1
A33: Peñaflor | B33: 1
A34: Talagante | B34: 1
A35: Total general | B35: 46

Sheet Comuna por Sector
A1: N° | B1: Comuna | C1: Sector | D1: Provincia | E1: Zona
A2: 11 | B2: Las Condes | C2: Nororiente (Sector Oriente) | D2: Santiago | E2: 1
A3: 12 | B3: Vitacura | C3: Nororiente (Sector Oriente) | D3: Santiago | E3: 1
A4: 13 | B4: Lo Barnechea | C4: Nororiente (Sector Oriente) | D4: Santiago | E4: 1
A5: 14 | B5: Providencia | C5: Nororiente (Sector Oriente) | D5: Santiago | E5: 1
A6: 15 | B6: La Reina | C6: Nororiente (Sector Oriente) | D6: Santiago | E6: 1
A7: 16 | B7: Ñuñoa | C7: Nororiente (Sector Oriente) | D7: Santiago | E7: 1
A8: 28 | B8: La Florida | C8: Suroriente | D8: Santiago | E8: 1
A9: 29 | B9: Peñalolén | C9: Suroriente | D9: Santiago | E9: 1
A10: 30 | B10: Macul | C10: Suroriente | D10: Santiago | E10: 1
A11: 31 | B11: Puente Alto | C11: Suroriente | D11: Cordillera | E11: 1
A12: 32 | B12: Pirque | C12: Suroriente | D12: Cordillera | E12: 1
A13: 52 | B13: San José de Maipo | C13: Suroriente | D13: Cordillera | E13: 1
... A53: 38 | B53: Talagante | C53: Surponiente | D53: Talagante | E53: 6
